Workbook

Sheet Principal
A1: PARECER TÉCNICO: AVALIAÇÃO HEURÍSTICA
A2: Nome do sistema: | B2: Lumora
A3: Acesso (link) para protótipo/sistema: | B3: https://github.com/ICEI-PUC-Minas-PMV-SI/pmv-si-2026-1-pe3-t4-lumora/tree/main/src/aplicacao
A4: Nomes dos integrantes da Equipe: | B4: Caroline Teresa Selvecki, Divino Armando Batista Soares, Felipe Fernandes Jardim, Kamila Júlia do Espírito Santo, Luiza Trevenzoli Castor, Nicole Mikaely Amaral Santos Silva
A5: Número | B5: Título da Heurística | C5: Descrição da Heurística | D5: Problemas encontrados | E5: Sugestões
A6: 1 | B6: Visibilidade do status do sistema | C6: O sistema sempre deve manter os usuários informados sobre o que está acontecendo, por meio de feedback apropriado dentro de um prazo razoável. | D6: =Consolidação!A27 -> 1. O sistema apresenta o dia selecionado, tarefas e agenda de forma clara. Porém, ao marcar uma tarefa como concluída, não existe uma confirmação visual muito evidente além do texto riscado. 2. Não há feedback visual claro após adicionar, editar ou excluir uma tarefa. O usuário pode ficar em dúvida se a ação foi executada com sucesso. 3. Não foram encontrados problemas. A página comunica claramente seu propósito e conteúdo em todas as seções. 4. O progresso do timer é exibido visualmente e o sistema informa quando o tempo termina. Entretanto, não há um alerta sonoro para chamar a atenção do usuário ao final da contagem. 5. Quando o usuário tenta logar com o botão "Entrar com Google" o sistema não responde e não mostra nenhuma mensagem, deixando o usuário sem informação do que está acontecendo. 6. Não há feedback visual claro após adicionar ou editar foto de perfil e nome de usuário. O usuário pode ficar em dúvida se a ação foi executada com sucesso. | E6: =Consolidação!B27 -> 1. O sistema apresenta o dia selecionado, tarefas e agenda de forma clara. Porém, ao marcar uma tarefa como concluída, não existe uma confirmação visual muito evidente além do texto riscado. 2. Exibir mensagens de confirmação (toast/snackbar), como "Tarefa adicionada com sucesso" ou "Tarefa removida". 3. Manter a configuração atual. 4. Adicionar um aviso sonoro ao término do timer. Exibir notificação mesmo com a aba minimizada. 5. Remover o botão, configurar para que o usuário possa utilizá-lo ou informar ao usuário de que a opção não está disponível no momento. 6. Exibir uma mensagem após a execução da tarefa como " nome de usuário ou foto de perfil editado(a) com sucesso".
A7: 2 | B7: Correspondência entre o sistema e o mundo real | C7: O sistema deve falar o idioma do usuário, com palavras, frases e conceitos familiares ao usuário, em vez de termos orientados ao sistema. Siga as convenções do mundo real, fazendo as informações aparecerem em uma ordem natural e lógica. | D7: =Consolidação!A28 -> 1. A maior parte dos termos utilizados é familiar ao usuário, como "Hoje", "Amanhã", "Agenda do Dia" e "Tarefas". Entretanto, usuários podem não compreender imediatamente a diferença entre a visualização semanal e a agenda diária. 2. O sistema utiliza os termos "Nova Tarefa" e "Nova Missão" para a mesma funcionalidade, podendo gerar confusão. 3. Não foram encontrados problemas. Os textos utilizam linguagem acessível e direta ("Organize sua rotina. No seu ritmo.", "Tarefas do Dia", "Modo Foco"), compatíveis com o vocabulário do público-alvo. 4. Não foram identificados problemas relevantes. 5. Não foram encontrados problemas. 6. Não há problemas relevantes. | E7: =Consolidação!B28 -> 1. O usuário consegue navegar entre semanas e selecionar qualquer dia da semana exibida. Entretanto, não existe uma forma rápida de retornar para uma data específica distante. 2. Não foram identificados problemas relevantes nesta heurística. 3. Não foram encontrados problemas. A navegação fixa com links âncora permite ao usuário ir e voltar entre seções livremente. O scroll suave contribui para a orientação espacial na página. 4. Não foram identificados problemas relevantes. 5. Não foram encontrados problemas, se o usuário clicar em criar uma nova conta, mas já possuir uma conta, ele tem a opção de voltar à tela de login. 6. Não há problemas relevantes.
A8: 3 | B8: Controle e liberdade do usuário | C8: Os usuários geralmente escolhem as funções do sistema por engano e precisam de uma "saída de emergência" claramente marcada para deixar o estado indesejado sem ter que passar por um diálogo prolongado. Suporte para desfazer e refazer. | D8: =Consolidação!A29 -> 1. O usuário consegue navegar entre semanas e selecionar qualquer dia da semana exibida. Entretanto, não existe uma forma rápida de retornar para uma data específica distante. 2. Não foram identificados problemas relevantes nesta heurística. 3. Não foram encontrados problemas. A navegação fixa com links âncora permite ao usuário ir e voltar entre seções livremente. O scroll suave contribui para a orientação espacial na página. 4. Não foram identificados problemas relevantes. 5. Não foram encontrados problemas, se o usuário clicar em criar uma nova conta, mas já possuir uma conta, ele tem a opção de voltar à tela de login. 6. Não há problemas relevantes. | E8: =Consolidação!B29 -> 1. Implementar um seletor de data (Date Picker) para permitir navegação direta para qualquer dia. 2. Como melhoria futura, poderia ser adicionada uma opção de "Desfazer" após a exclusão para aumentar ainda mais o controle do usuário. 3. Manter a configuração atual. 4. Manter os controles acessíveis durante toda a execução. 5. Manter a configuração do sistema 6. -
A9: 4 | B9: Consistência e padrões | C9: Os usuários não devem se perguntar se palavras, situações ou ações diferentes significam a mesma coisa. | D9: =Consolidação!A30 -> 1. Os componentes seguem o mesmo padrão visual, utilizando a mesma paleta de cores, tipografia e estilo dos botões. Não foram encontrados problemas significativos. 2. Há inconsistência terminológica entre "Tarefa" e "Missão". 3. O link "Ver o App" aparece duplicado na navegação, uma vez nos nav-links (visível no menu) e outra vez como botão CTA separado. Em telas menores o CTA é ocultado via CSS, mas em desktop ambos ficam visíveis simultaneamente, o que pode causar estranhamento visual por repetição. 4. Não foram identificadas inconsistências relevantes. 5. Não foram encontrados problemas. 6. Não há problemas relevantes. | E9: =Consolidação!B30 -> 1. Manter a padronização visual em futuras funcionalidades do sistema. 2. Padronizar termos, ícones e nomenclaturas em todas as telas. 3. Manter apenas o botão CTA destacado na navbar, removendo a entrada duplicada dentro dos nav-links, ou diferenciá-los visualmente com propósitos distintos. 4. Manter a padronização visual em novas funcionalidades. 5. Manter a configuração do sistema 6. -
A10: 5 | B10: Prevenção de erros | C10: Elimine condições propensas a erros ou verifique-as e apresente aos usuários uma opção de confirmação antes que eles se comprometam com a ação. | D10: =Consolidação!A31 -> 1. Atualmente o sistema possui poucas ações críticas. Entretanto, futuras funcionalidades envolvendo exclusão de tarefas podem gerar erros de uso. 2. O sistema ajuda a prevenir exclusões acidentais por meio de uma confirmação antes da remoção da tarefa. No entanto, não foram observadas validações visíveis para campos obrigatórios no cadastro de tarefas. 3. Não foram encontrados problemas. A página é essencialmente informativa e de navegação, sem formulários ou campos de entrada que possam gerar erros de preenchimento. 4. O sistema impede alterações no tempo enquanto o timer está em execução, evitando mudanças acidentais. Porém, o botão de reiniciar não solicita confirmação. 5. Não foram encontrados problemas. 6. Não há confirmação visual clara antes de editar ou adicionar foto de perfil e nome de usuário. | E10: =Consolidação!B31 -> 1. Adicionar confirmações para ações destrutivas, como exclusão de tarefas ou eventos. 2. Manter a confirmação de exclusão e implementar validações visuais para campos obrigatórios e formatos inválidos. 3. Manter a configuração atual. 4. Adicionar confirmação antes de reiniciar uma sessão em andamento. 5. Manter a configuração do sistema 6. Exibir uma mensagem para confirmação da execução da ação. Exemplo: "Você deseja mesmo editar o nome de usuário de"Nicole " para"Nicole 123 "Nicole123" ?"
A11: 6 | B11: Reconhecimento em vez de recordação | C11: Minimize a carga de memória do usuário, tornando objetos, ações e opções visíveis. O usuário não deve ter que lembrar informações de uma parte do diálogo para outra. As instruções de uso do sistema devem ser visíveis ou facilmente recuperáveis sempre que apropriado. | D11: =Consolidação!A32 -> 1. As informações importantes ficam visíveis na tela, como tarefas do dia, agenda e data selecionada. O usuário não precisa memorizar informações para utilizar o sistema. 2. Não foram identificados problemas relevantes. 3. Não foram encontrados problemas. A navegação fixa com rótulos claros (Sobre, Funcionalidades, Screenshots, Equipe) permite que o usuário identifique visualmente onde está e para onde pode ir, sem necessidade de memorização. 4. Não foram identificados problemas relevantes. 5. Não foram encontrados problemas, a tela de login é limpa e sugestiva às ações do usuário. 6. Não há problemas relevantes. | E11: =Consolidação!B32 -> 1. Continuar priorizando informações visíveis e reduzir a necessidade de navegação excessiva. 2. Manter o padrão atual de identificação visual e textual dos elementos da interface. 3. Manter a configuração atual. 4. Manter a organização atual da interface. 5. Manter a configuração do sistema 6. -
A12: 7 | B12: Flexibilidade e eficiência de uso | C12: Aceleradores - invisíveis para o usuário iniciante - geralmente aceleram a interação do usuário experiente, de modo que o sistema possa atender a usuários inexperientes e experientes. Permita que os usuários adaptem ações frequentes. | D12: =Consolidação!A33 -> 1. Usuários iniciantes conseguem utilizar o calendário facilmente. Porém, usuários mais experientes podem sentir falta de atalhos ou navegação mais rápida. 2. Não foram identificados problemas relevantes 3. O cursor personalizado é ativado apenas para telas acima de 600px. Em dispositivos móveis a experiência é padrão, o que é adequado. Porém, não há indicador de seção ativa no menu de navegação, o que reduziria a eficiência de orientação para usuários experientes. 4. O seletor de tempo existe, mas não comunica visualmente que é interativo, o número parece texto estático, o que pode confundir usuários na primeira vez. 5. Não foram encontrados problemas. 6. Não há problemas relevantes. | E12: =Consolidação!B33 -> 1. Adicionar atalhos de teclado e filtros rápidos para melhorar a produtividade. 2. Manter a organização atual das ações rápidas, garantindo que continuem facilmente acessíveis aos usuários. 3. Implementar destaque visual no link de navegação correspondente à seção visível no momento, melhorando a orientação para todos os perfis de usuário. 4. Adicionar indicador visual (ícone de edição, sublinhado ou destaque) para sinalizar que o tempo é editável. 5. Manter a configuração do sistema 6. -
A13: 8 | B13: Design estético e minimalista | C13: Os diálogos não devem conter informações irrelevantes ou raramente necessárias. Cada unidade extra de informação em um diálogo concorre com as unidades relevantes de informação e diminui sua visibilidade relativa. | D13: =Consolidação!A34 -> 1. A interface possui visual limpo, organizado e agradável, utilizando uma paleta suave e poucas distrações visuais. Não foram identificados problemas relevantes. 2. O design é limpo e organizado, porém alguns textos possuem contraste baixo com o fundo, dificultando a leitura. 3. Não foram encontrados problemas. O layout é limpo, com hierarquia visual clara, paleta coesa e sem elementos decorativos excessivos. As seções são bem delimitadas e o conteúdo é direto ao ponto. 4. Não foram identificados problemas relevantes. 5. Não foram encontrados problemas. 6. Não há problemas relevantes. | E13: =Consolidação!B34 -> 1. Manter o design minimalista e evitar excesso de informações na tela principal. 2. Melhorar o contraste dos rótulos secundários e informações menores para aumentar a acessibilidade. 3. Manter a configuração atual. 4. Manter o design simples e objetivo. 5. Manter a configuração do sistema 6. -
A14: 9 | B14: Ajude os usuários a reconhecer, diagnosticar e recuperar de erros | C14: As mensagens de erro devem ser expressas em linguagem simples (sem códigos), indicar com precisão o problema e sugerir construtivamente uma solução. | D14: =Consolidação!A35 -> 1. Não existem mensagens de erro porque a aplicação ainda não possui integração com backend. Em futuras versões, falhas de carregamento ou salvamento podem não ficar claras ao usuário. 2. Não são apresentadas mensagens de erro ou orientações quando ocorre um problema de preenchimento ou operação inválida. 3. Não se aplica diretamente, pois a landing page não possui interações que gerem estados de erro (sem formulários, sem login, sem buscas). A página é essencialmente informativa e não expõe o usuário a situações de erro. 4. Não há mensagens específicas orientando o usuário caso ocorra algum erro ou ação inválida. 5. Não foram encontrados problemas, as mensagens de erro de senha ou e-mail são claras e objetivas 6. Não há mensagens para problemas de erro ou operação inválida. | E14: =Consolidação!B35 -> 1. Implementar mensagens amigáveis de erro e feedback para operações futuras envolvendo banco de dados ou APIs. 2. Exibir mensagens claras explicando o erro e orientando o usuário sobre como corrigi-lo. 3. Manter a configuração atual. 4. Exibir mensagens explicativas quando alguma ação não puder ser realizada. 5. Manter a configuração do sistema 6. Adicionar mensagens para problemas de erro ou operação inválida que oriente o usuário sobre como corrigi-lo.
A15: 10 | B15: Ajuda e documentação | C15: Mesmo que seja melhor se o sistema puder ser usado sem documentação, pode ser necessário fornecer ajuda e documentação. Essas informações devem ser fáceis de pesquisar, focadas na tarefa do usuário, listar etapas concretas a serem executadas e não serem muito grandes. | D15: =Consolidação!A36 -> 1. Não há uma seção de ajuda ou explicação das funcionalidades para novos usuários. Usuários podem precisar explorar a interface para compreender todas as funcionalidades. 2. Não há opção visível de ajuda, tutorial inicial ou seção de dúvidas frequentes. 3. Não foram encontrados problemas. A landing page é autoexplicativa, com descrições claras de cada funcionalidade do app nas feature cards. O público-alvo consegue compreender o propósito do sistema sem necessidade de documentação adicional. 4. O sistema é simples de usar, mas não possui uma área de ajuda ou orientações para novos usuários. 5. A tela de login é intuitiva e autoexplicativa, seguindo padrões de outros sistemas já existentes, portanto dispensando documentação para acessar. 6. Não há nenhuma seção para ajuda ou documentação. | E15: =Consolidação!B36 -> 1. Adicionar uma tela de onboarding, tutorial inicial ou seção de ajuda explicando os recursos do calendário. 2. Adicionar um guia rápido de utilização, FAQ ou tour inicial para novos usuários. 3. Manter a configuração atual. 4. Adicionar uma breve explicação das funcionalidades na primeira utilização do sistema. 5. Manter a configuração do sistema 6. Adicionar uma área visível para ajuda e explicação das funcionando com exemplos para novos usuários.
A17: Referência | B17: “10 Heurísticas de usabilidade para o design de interface do usuário” - por Jakob Nielsen em 24 de abril de 1994
B18: https://www.nngroup.com/articles/ten-usability-heuristics/

Sheet Parecer 1 - Caroline
A1: PARECER TÉCNICO: AVALIAÇÃO HEURÍSTICA
A2: Nome do sistema: | B2: Lumora
A3: Acesso (link) para protótipo/sistema: | B3: https://github.com/ICEI-PUC-Minas-PMV-SI/pmv-si-2026-1-pe3-t4-lumora/tree/55bab6ae1f43c5f7058ad9a66fe8e4b4e95b5959/docs/apresentacao
A4: Nomes dos integrantes da Equipe: | B4: Caroline Teresa Selvecki
A5: Número | B5: Título da Heurística | C5: Descrição da Heurística | D5: Problemas encontrados | E5: Sugestões
A6: 1 | B6: Visibilidade do status do sistema | C6: O sistema sempre deve manter os usuários informados sobre o que está acontecendo, por meio de feedback apropriado dentro de um prazo razoável. | D6: O sistema apresenta o dia selecionado, tarefas e agenda de forma clara. Porém, ao marcar uma tarefa como concluída, não existe uma confirmação visual muito evidente além do texto riscado. | E6: Adicionar uma pequena animação, alteração de cor ou mensagem visual indicando que a tarefa foi concluída com sucesso.
A7: 2 | B7: Correspondência entre o sistema e o mundo real | C7: O sistema deve falar o idioma do usuário, com palavras, frases e conceitos familiares ao usuário, em vez de termos orientados ao sistema. Siga as convenções do mundo real, fazendo as informações aparecerem em uma ordem natural e lógica. | D7: A maior parte dos termos utilizados é familiar ao usuário, como "Hoje", "Amanhã", "Agenda do Dia" e "Tarefas". Entretanto, usuários podem não compreender imediatamente a diferença entre a visualização semanal e a agenda diária. | E7: Adicionar uma breve descrição ou tooltip explicando a função de cada seção na primeira utilização.
A8: 3 | B8: Controle e liberdade do usuário | C8: Os usuários geralmente escolhem as funções do sistema por engano e precisam de uma "saída de emergência" claramente marcada para deixar o estado indesejado sem ter que passar por um diálogo prolongado. Suporte para desfazer e refazer. | D8: O usuário consegue navegar entre semanas e selecionar qualquer dia da semana exibida. Entretanto, não existe uma forma rápida de retornar para uma data específica distante. | E8: Implementar um seletor de data (Date Picker) para permitir navegação direta para qualquer dia.
A9: 4 | B9: Consistência e padrões | C9: Os usuários não devem se perguntar se palavras, situações ou ações diferentes significam a mesma coisa. | D9: Os componentes seguem o mesmo padrão visual, utilizando a mesma paleta de cores, tipografia e estilo dos botões. Não foram encontrados problemas significativos. | E9: Manter a padronização visual em futuras funcionalidades do sistema.
A10: 5 | B10: Prevenção de erros | C10: Elimine condições propensas a erros ou verifique-as e apresente aos usuários uma opção de confirmação antes que eles se comprometam com a ação. | D10: Atualmente o sistema possui poucas ações críticas. Entretanto, futuras funcionalidades envolvendo exclusão de tarefas podem gerar erros de uso. | E10: Adicionar confirmações para ações destrutivas, como exclusão de tarefas ou eventos.
A11: 6 | B11: Reconhecimento em vez de recordação | C11: Minimize a carga de memória do usuário, tornando objetos, ações e opções visíveis. O usuário não deve ter que lembrar informações de uma parte do diálogo para outra. As instruções de uso do sistema devem ser visíveis ou facilmente recuperáveis sempre que apropriado. | D11: As informações importantes ficam visíveis na tela, como tarefas do dia, agenda e data selecionada. O usuário não precisa memorizar informações para utilizar o sistema. | E11: Continuar priorizando informações visíveis e reduzir a necessidade de navegação excessiva.
A12: 7 | B12: Flexibilidade e eficiência de uso | C12: Aceleradores - invisíveis para o usuário iniciante - geralmente aceleram a interação do usuário experiente, de modo que o sistema possa atender a usuários inexperientes e experientes. Permita que os usuários adaptem ações frequentes. | D12: Usuários iniciantes conseguem utilizar o calendário facilmente. Porém, usuários mais experientes podem sentir falta de atalhos ou navegação mais rápida. | E12: Adicionar atalhos de teclado e filtros rápidos para melhorar a produtividade.
A13: 8 | B13: Design estético e minimalista | C13: Os diálogos não devem conter informações irrelevantes ou raramente necessárias. Cada unidade extra de informação em um diálogo concorre com as unidades relevantes de informação e diminui sua visibilidade relativa. | D13: A interface possui visual limpo, organizado e agradável, utilizando uma paleta suave e poucas distrações visuais. Não foram identificados problemas relevantes. | E13: Manter o design minimalista e evitar excesso de informações na tela principal.
A14: 9 | B14: Ajude os usuários a reconhecer, diagnosticar e recuperar de erros | C14: As mensagens de erro devem ser expressas em linguagem simples (sem códigos), indicar com precisão o problema e sugerir construtivamente uma solução. | D14: Não existem mensagens de erro porque a aplicação ainda não possui integração com backend. Em futuras versões, falhas de carregamento ou salvamento podem não ficar claras ao usuário. | E14: Implementar mensagens amigáveis de erro e feedback para operações futuras envolvendo banco de dados ou APIs.
A15: 10 | B15: Ajuda e documentação | C15: Mesmo que seja melhor se o sistema puder ser usado sem documentação, pode ser necessário fornecer ajuda e documentação. Essas informações devem ser fáceis de pesquisar, focadas na tarefa do usuário, listar etapas concretas a serem executadas e não serem muito grandes. | D15: Não há uma seção de ajuda ou explicação das funcionalidades para novos usuários. Usuários podem precisar explorar a interface para compreender todas as funcionalidades. | E15: Adicionar uma tela de onboarding, tutorial inicial ou seção de ajuda explicando os recursos do calendário.
A17: Referência | B17: “10 Heurísticas de usabilidade para o design de interface do usuário” - por Jakob Nielsen em 24 de abril de 1994
B18: https://www.nngroup.com/articles/ten-usability-heuristics/

Sheet Parecer 2 - Divino
A1: PARECER TÉCNICO: AVALIAÇÃO HEURÍSTICA
A2: Nome do sistema: | B2: Lumora
A3: Acesso (link) para protótipo/sistema:
A4: Nomes dos integrantes da Equipe: | B4: Divino Armando Batista Soares
A5: Número | B5: Título da Heurística | C5: Descrição da Heurística | D5: Problemas encontrados | E5: Sugestões
A6: 1 | B6: Visibilidade do status do sistema | C6: O sistema sempre deve manter os usuários informados sobre o que está acontecendo, por meio de feedback apropriado dentro de um prazo razoável. | D6: Não há feedback visual claro após adicionar, editar ou excluir uma tarefa. O usuário pode ficar em dúvida se a ação foi executada com sucesso. | E6: Exibir mensagens de confirmação (toast/snackbar), como "Tarefa adicionada com sucesso" ou "Tarefa removida".
A7: 2 | B7: Correspondência entre o sistema e o mundo real | C7: O sistema deve falar o idioma do usuário, com palavras, frases e conceitos familiares ao usuário, em vez de termos orientados ao sistema. Siga as convenções do mundo real, fazendo as informações aparecerem em uma ordem natural e lógica. | D7: O sistema utiliza os termos "Nova Tarefa" e "Nova Missão" para a mesma funcionalidade, podendo gerar confusão. | E7: Padronizar a nomenclatura utilizando apenas "Tarefa" ou apenas "Missão" em todo o sistema.
A8: 3 | B8: Controle e liberdade do usuário | C8: Os usuários geralmente escolhem as funções do sistema por engano e precisam de uma "saída de emergência" claramente marcada para deixar o estado indesejado sem ter que passar por um diálogo prolongado. Suporte para desfazer e refazer. | D8: Não foram identificados problemas relevantes nesta heurística. | E8: Como melhoria futura, poderia ser adicionada uma opção de "Desfazer" após a exclusão para aumentar ainda mais o controle do usuário.
A9: 4 | B9: Consistência e padrões | C9: Os usuários não devem se perguntar se palavras, situações ou ações diferentes significam a mesma coisa. | D9: Há inconsistência terminológica entre "Tarefa" e "Missão". | E9: Padronizar termos, ícones e nomenclaturas em todas as telas.
A10: 5 | B10: Prevenção de erros | C10: Elimine condições propensas a erros ou verifique-as e apresente aos usuários uma opção de confirmação antes que eles se comprometam com a ação. | D10: O sistema ajuda a prevenir exclusões acidentais por meio de uma confirmação antes da remoção da tarefa. No entanto, não foram observadas validações visíveis para campos obrigatórios no cadastro de tarefas. | E10: Manter a confirmação de exclusão e implementar validações visuais para campos obrigatórios e formatos inválidos.
A11: 6 | B11: Reconhecimento em vez de recordação | C11: Minimize a carga de memória do usuário, tornando objetos, ações e opções visíveis. O usuário não deve ter que lembrar informações de uma parte do diálogo para outra. As instruções de uso do sistema devem ser visíveis ou facilmente recuperáveis sempre que apropriado. | D11: Não foram identificados problemas relevantes. | E11: Manter o padrão atual de identificação visual e textual dos elementos da interface.
A12: 7 | B12: Flexibilidade e eficiência de uso | C12: Aceleradores - invisíveis para o usuário iniciante - geralmente aceleram a interação do usuário experiente, de modo que o sistema possa atender a usuários inexperientes e experientes. Permita que os usuários adaptem ações frequentes. | D12: Não foram identificados problemas relevantes | E12: Manter a organização atual das ações rápidas, garantindo que continuem facilmente acessíveis aos usuários.
A13: 8 | B13: Design estético e minimalista | C13: Os diálogos não devem conter informações irrelevantes ou raramente necessárias. Cada unidade extra de informação em um diálogo concorre com as unidades relevantes de informação e diminui sua visibilidade relativa. | D13: O design é limpo e organizado, porém alguns textos possuem contraste baixo com o fundo, dificultando a leitura. | E13: Melhorar o contraste dos rótulos secundários e informações menores para aumentar a acessibilidade.
A14: 9 | B14: Ajude os usuários a reconhecer, diagnosticar e recuperar de erros | C14: As mensagens de erro devem ser expressas em linguagem simples (sem códigos), indicar com precisão o problema e sugerir construtivamente uma solução. | D14: Não são apresentadas mensagens de erro ou orientações quando ocorre um problema de preenchimento ou operação inválida. | E14: Exibir mensagens claras explicando o erro e orientando o usuário sobre como corrigi-lo.
A15: 10 | B15: Ajuda e documentação | C15: Mesmo que seja melhor se o sistema puder ser usado sem documentação, pode ser necessário fornecer ajuda e documentação. Essas informações devem ser fáceis de pesquisar, focadas na tarefa do usuário, listar etapas concretas a serem executadas e não serem muito grandes. | D15: Não há opção visível de ajuda, tutorial inicial ou seção de dúvidas frequentes. | E15: Adicionar um guia rápido de utilização, FAQ ou tour inicial para novos usuários.
A17: Referência | B17: “10 Heurísticas de usabilidade para o design de interface do usuário” - por Jakob Nielsen em 24 de abril de 1994
B18: https://www.nngroup.com/articles/ten-usability-heuristics/

Sheet Parecer 6 - Nicole
A1: PARECER TÉCNICO: AVALIAÇÃO HEURÍSTICA
A2: Nome do sistema: | B2: Lumora
A3: Acesso (link) para protótipo/sistema: | B3: https://github.com/ICEI-PUC-Minas-PMV-SI/pmv-si-2026-1-pe3-t4-lumora/tree/main/src/aplicacao/perfil
A4: Nomes dos integrantes da Equipe: | B4: Nicole Mikaely Amaral Santos Silva
A5: Número | B5: Título da Heurística | C5: Descrição da Heurística | D5: Problemas encontrados | E5: Sugestões
A6: 1 | B6: Visibilidade do status do sistema | C6: O sistema sempre deve manter os usuários informados sobre o que está acontecendo, por meio de feedback apropriado dentro de um prazo razoável. | D6: Não há feedback visual claro após adicionar ou editar foto de perfil e nome de usuário. O usuário pode ficar em dúvida se a ação foi executada com sucesso. | E6: Exibir uma mensagem após a execução da tarefa como " nome de usuário ou foto de perfil editado(a) com sucesso".
A7: 2 | B7: Correspondência entre o sistema e o mundo real | C7: O sistema deve falar o idioma do usuário, com palavras, frases e conceitos familiares ao usuário, em vez de termos orientados ao sistema. Siga as convenções do mundo real, fazendo as informações aparecerem em uma ordem natural e lógica. | D7: Não há problemas relevantes. | E7: -
A8: 3 | B8: Controle e liberdade do usuário | C8: Os usuários geralmente escolhem as funções do sistema por engano e precisam de uma "saída de emergência" claramente marcada para deixar o estado indesejado sem ter que passar por um diálogo prolongado. Suporte para desfazer e refazer. | D8: Não há problemas relevantes. | E8: -
A9: 4 | B9: Consistência e padrões | C9: Os usuários não devem se perguntar se palavras, situações ou ações diferentes significam a mesma coisa. | D9: Não há problemas relevantes. | E9: -
A10: 5 | B10: Prevenção de erros | C10: Elimine condições propensas a erros ou verifique-as e apresente aos usuários uma opção de confirmação antes que eles se comprometam com a ação. | D10: Não há confirmação visual clara antes de editar ou adicionar foto de perfil e nome de usuário. | E10: Exibir uma mensagem para confirmação da execução da ação. Exemplo: "Você deseja mesmo editar o nome de usuário de"Nicole " para"Nicole 123 "Nicole123" ?"
A11: 6 | B11: Reconhecimento em vez de recordação | C11: Minimize a carga de memória do usuário, tornando objetos, ações e opções visíveis. O usuário não deve ter que lembrar informações de uma parte do diálogo para outra. As instruções de uso do sistema devem ser visíveis ou facilmente recuperáveis sempre que apropriado. | D11: Não há problemas relevantes. | E11: -
A12: 7 | B12: Flexibilidade e eficiência de uso | C12: Aceleradores - invisíveis para o usuário iniciante - geralmente aceleram a interação do usuário experiente, de modo que o sistema possa atender a usuários inexperientes e experientes. Permita que os usuários adaptem ações frequentes. | D12: Não há problemas relevantes. | E12: -
A13: 8 | B13: Design estético e minimalista | C13: Os diálogos não devem conter informações irrelevantes ou raramente necessárias. Cada unidade extra de informação em um diálogo concorre com as unidades relevantes de informação e diminui sua visibilidade relativa. | D13: Não há problemas relevantes. | E13: -
A14: 9 | B14: Ajude os usuários a reconhecer, diagnosticar e recuperar de erros | C14: As mensagens de erro devem ser expressas em linguagem simples (sem códigos), indicar com precisão o problema e sugerir construtivamente uma solução. | D14: Não há mensagens para problemas de erro ou operação inválida. | E14: Adicionar mensagens para problemas de erro ou operação inválida que oriente o usuário sobre como corrigi-lo.
A15: 10 | B15: Ajuda e documentação | C15: Mesmo que seja melhor se o sistema puder ser usado sem documentação, pode ser necessário fornecer ajuda e documentação. Essas informações devem ser fáceis de pesquisar, focadas na tarefa do usuário, listar etapas concretas a serem executadas e não serem muito grandes. | D15: Não há nenhuma seção para ajuda ou documentação. | E15: Adicionar uma área visível para ajuda e explicação das funcionando com exemplos para novos usuários.
A17: Referência | B17: “10 Heurísticas de usabilidade para o design de interface do usuário” - por Jakob Nielsen em 24 de abril de 1994
B18: https://www.nngroup.com/articles/ten-usability-heuristics/

Sheet Parecer 3 - Felipe
A1: PARECER TÉCNICO: AVALIAÇÃO HEURÍSTICA
A2: Nome do sistema: | B2: Lumora - Landing Page de Apresentação
A3: Acesso (link) para protótipo/sistema: | B3: https://github.com/ICEI-PUC-Minas-PMV-SI/pmv-si-2026-1-pe3-t4-lumora/tree/55bab6ae1f43c5f7058ad9a66fe8e4b4e95b5959/docs/apresentacao
A4: Nome do interante da Equipe: | B4: Felipe Fernandes Jardim
A5: Número | B5: Título da Heurística | C5: Descrição da Heurística | D5: Problemas encontrados | E5: Sugestões
A6: 1 | B6: Visibilidade do status do sistema | C6: O sistema sempre deve manter os usuários informados sobre o que está acontecendo, por meio de feedback apropriado dentro de um prazo razoável. | D6: Não foram encontrados problemas. A página comunica claramente seu propósito e conteúdo em todas as seções. | E6: Manter a configuração atual.
A7: 2 | B7: Correspondência entre o sistema e o mundo real | C7: O sistema deve falar o idioma do usuário, com palavras, frases e conceitos familiares ao usuário, em vez de termos orientados ao sistema. Siga as convenções do mundo real, fazendo as informações aparecerem em uma ordem natural e lógica. | D7: Não foram encontrados problemas. Os textos utilizam linguagem acessível e direta ("Organize sua rotina. No seu ritmo.", "Tarefas do Dia", "Modo Foco"), compatíveis com o vocabulário do público-alvo. | E7: Manter a configuração atual.
A8: 3 | B8: Controle e liberdade do usuário | C8: Os usuários geralmente escolhem as funções do sistema por engano e precisam de uma "saída de emergência" claramente marcada para deixar o estado indesejado sem ter que passar por um diálogo prolongado. Suporte para desfazer e refazer. | D8: Não foram encontrados problemas. A navegação fixa com links âncora permite ao usuário ir e voltar entre seções livremente. O scroll suave contribui para a orientação espacial na página. | E8: Manter a configuração atual.
A9: 4 | B9: Consistência e padrões | C9: Os usuários não devem se perguntar se palavras, situações ou ações diferentes significam a mesma coisa. | D9: O link "Ver o App" aparece duplicado na navegação, uma vez nos nav-links (visível no menu) e outra vez como botão CTA separado. Em telas menores o CTA é ocultado via CSS, mas em desktop ambos ficam visíveis simultaneamente, o que pode causar estranhamento visual por repetição. | E9: Manter apenas o botão CTA destacado na navbar, removendo a entrada duplicada dentro dos nav-links, ou diferenciá-los visualmente com propósitos distintos.
A10: 5 | B10: Prevenção de erros | C10: Elimine condições propensas a erros ou verifique-as e apresente aos usuários uma opção de confirmação antes que eles se comprometam com a ação. | D10: Não foram encontrados problemas. A página é essencialmente informativa e de navegação, sem formulários ou campos de entrada que possam gerar erros de preenchimento. | E10: Manter a configuração atual.
A11: 6 | B11: Reconhecimento em vez de recordação | C11: Minimize a carga de memória do usuário, tornando objetos, ações e opções visíveis. O usuário não deve ter que lembrar informações de uma parte do diálogo para outra. As instruções de uso do sistema devem ser visíveis ou facilmente recuperáveis sempre que apropriado. | D11: Não foram encontrados problemas. A navegação fixa com rótulos claros (Sobre, Funcionalidades, Screenshots, Equipe) permite que o usuário identifique visualmente onde está e para onde pode ir, sem necessidade de memorização. | E11: Manter a configuração atual.
A12: 7 | B12: Flexibilidade e eficiência de uso | C12: Aceleradores - invisíveis para o usuário iniciante - geralmente aceleram a interação do usuário experiente, de modo que o sistema possa atender a usuários inexperientes e experientes. Permita que os usuários adaptem ações frequentes. | D12: O cursor personalizado é ativado apenas para telas acima de 600px. Em dispositivos móveis a experiência é padrão, o que é adequado. Porém, não há indicador de seção ativa no menu de navegação, o que reduziria a eficiência de orientação para usuários experientes. | E12: Implementar destaque visual no link de navegação correspondente à seção visível no momento, melhorando a orientação para todos os perfis de usuário.
A13: 8 | B13: Design estético e minimalista | C13: Os diálogos não devem conter informações irrelevantes ou raramente necessárias. Cada unidade extra de informação em um diálogo concorre com as unidades relevantes de informação e diminui sua visibilidade relativa. | D13: Não foram encontrados problemas. O layout é limpo, com hierarquia visual clara, paleta coesa e sem elementos decorativos excessivos. As seções são bem delimitadas e o conteúdo é direto ao ponto. | E13: Manter a configuração atual.
A14: 9 | B14: Ajude os usuários a reconhecer, diagnosticar e recuperar de erros | C14: As mensagens de erro devem ser expressas em linguagem simples (sem códigos), indicar com precisão o problema e sugerir construtivamente uma solução. | D14: Não se aplica diretamente, pois a landing page não possui interações que gerem estados de erro (sem formulários, sem login, sem buscas). A página é essencialmente informativa e não expõe o usuário a situações de erro. | E14: Manter a configuração atual.
A15: 10 | B15: Ajuda e documentação | C15: Mesmo que seja melhor se o sistema puder ser usado sem documentação, pode ser necessário fornecer ajuda e documentação. Essas informações devem ser fáceis de pesquisar, focadas na tarefa do usuário, listar etapas concretas a serem executadas e não serem muito grandes. | D15: Não foram encontrados problemas. A landing page é autoexplicativa, com descrições claras de cada funcionalidade do app nas feature cards. O público-alvo consegue compreender o propósito do sistema sem necessidade de documentação adicional. | E15: Manter a configuração atual.
A17: Referência | B17: “10 Heurísticas de usabilidade para o design de interface do usuário” - por Jakob Nielsen em 24 de abril de 1994
B18: https://www.nngroup.com/articles/ten-usability-heuristics/

Sheet Parecer 4 - Kamila
A1: PARECER TÉCNICO: AVALIAÇÃO HEURÍSTICA
A2: Nome do sistema: | B2: Lumora
A3: Acesso (link) para protótipo/sistema:
A4: Nomes dos integrantes da Equipe: | B4: Kamila Júlia do Espírito Santo
A5: Número | B5: Título da Heurística | C5: Descrição da Heurística | D5: Problemas encontrados | E5: Sugestões
A6: 1 | B6: Visibilidade do status do sistema | C6: O sistema sempre deve manter os usuários informados sobre o que está acontecendo, por meio de feedback apropriado dentro de um prazo razoável. | D6: O progresso do timer é exibido visualmente e o sistema informa quando o tempo termina. Entretanto, não há um alerta sonoro para chamar a atenção do usuário ao final da contagem. | E6: Adicionar um aviso sonoro ao término do timer. Exibir notificação mesmo com a aba minimizada.
A7: 2 | B7: Correspondência entre o sistema e o mundo real | C7: O sistema deve falar o idioma do usuário, com palavras, frases e conceitos familiares ao usuário, em vez de termos orientados ao sistema. Siga as convenções do mundo real, fazendo as informações aparecerem em uma ordem natural e lógica. | D7: Não foram identificados problemas relevantes. | E7: Manter a linguagem atual do sistema.
A8: 3 | B8: Controle e liberdade do usuário | C8: Os usuários geralmente escolhem as funções do sistema por engano e precisam de uma "saída de emergência" claramente marcada para deixar o estado indesejado sem ter que passar por um diálogo prolongado. Suporte para desfazer e refazer. | D8: Não foram identificados problemas relevantes. | E8: Manter os controles acessíveis durante toda a execução.
A9: 4 | B9: Consistência e padrões | C9: Os usuários não devem se perguntar se palavras, situações ou ações diferentes significam a mesma coisa. | D9: Não foram identificadas inconsistências relevantes. | E9: Manter a padronização visual em novas funcionalidades.
A10: 5 | B10: Prevenção de erros | C10: Elimine condições propensas a erros ou verifique-as e apresente aos usuários uma opção de confirmação antes que eles se comprometam com a ação. | D10: O sistema impede alterações no tempo enquanto o timer está em execução, evitando mudanças acidentais. Porém, o botão de reiniciar não solicita confirmação. | E10: Adicionar confirmação antes de reiniciar uma sessão em andamento.
A11: 6 | B11: Reconhecimento em vez de recordação | C11: Minimize a carga de memória do usuário, tornando objetos, ações e opções visíveis. O usuário não deve ter que lembrar informações de uma parte do diálogo para outra. As instruções de uso do sistema devem ser visíveis ou facilmente recuperáveis sempre que apropriado. | D11: Não foram identificados problemas relevantes. | E11: Manter a organização atual da interface.
A12: 7 | B12: Flexibilidade e eficiência de uso | C12: Aceleradores - invisíveis para o usuário iniciante - geralmente aceleram a interação do usuário experiente, de modo que o sistema possa atender a usuários inexperientes e experientes. Permita que os usuários adaptem ações frequentes. | D12: O seletor de tempo existe, mas não comunica visualmente que é interativo, o número parece texto estático, o que pode confundir usuários na primeira vez. | E12: Adicionar indicador visual (ícone de edição, sublinhado ou destaque) para sinalizar que o tempo é editável.
A13: 8 | B13: Design estético e minimalista | C13: Os diálogos não devem conter informações irrelevantes ou raramente necessárias. Cada unidade extra de informação em um diálogo concorre com as unidades relevantes de informação e diminui sua visibilidade relativa. | D13: Não foram identificados problemas relevantes. | E13: Manter o design simples e objetivo.
A14: 9 | B14: Ajude os usuários a reconhecer, diagnosticar e recuperar de erros | C14: As mensagens de erro devem ser expressas em linguagem simples (sem códigos), indicar com precisão o problema e sugerir construtivamente uma solução. | D14: Não há mensagens específicas orientando o usuário caso ocorra algum erro ou ação inválida. | E14: Exibir mensagens explicativas quando alguma ação não puder ser realizada.
A15: 10 | B15: Ajuda e documentação | C15: Mesmo que seja melhor se o sistema puder ser usado sem documentação, pode ser necessário fornecer ajuda e documentação. Essas informações devem ser fáceis de pesquisar, focadas na tarefa do usuário, listar etapas concretas a serem executadas e não serem muito grandes. | D15: O sistema é simples de usar, mas não possui uma área de ajuda ou orientações para novos usuários. | E15: Adicionar uma breve explicação das funcionalidades na primeira utilização do sistema.
A17: Referência | B17: “10 Heurísticas de usabilidade para o design de interface do usuário” - por Jakob Nielsen em 24 de abril de 1994
B18: https://www.nngroup.com/articles/ten-usability-heuristics/

Sheet Parecer 5 - Luiza
A1: PARECER TÉCNICO: AVALIAÇÃO HEURÍSTICA
A2: Nome do sistema: | B2: Lumora - Tela login
A3: Acesso (link) para protótipo/sistema:
A4: Nomes dos integrantes da Equipe: | B4: Caroline Teresa Selvecki, Divino Armando Batista Soares, Felipe Fernandes Jardim, Kamila Júlia do Espírito Santo, Luiza Trevenzoli Castor, Nicole Mikaely Amaral Santos Silva
A5: Número | B5: Título da Heurística | C5: Descrição da Heurística | D5: Problemas encontrados | E5: Sugestões
A6: 1 | B6: Visibilidade do status do sistema | C6: O sistema sempre deve manter os usuários informados sobre o que está acontecendo, por meio de feedback apropriado dentro de um prazo razoável. | D6: Quando o usuário tenta logar com o botão "Entrar com Google" o sistema não responde e não mostra nenhuma mensagem, deixando o usuário sem informação do que está acontecendo. | E6: Remover o botão, configurar para que o usuário possa utilizá-lo ou informar ao usuário de que a opção não está disponível no momento.
A7: 2 | B7: Correspondência entre o sistema e o mundo real | C7: O sistema deve falar o idioma do usuário, com palavras, frases e conceitos familiares ao usuário, em vez de termos orientados ao sistema. Siga as convenções do mundo real, fazendo as informações aparecerem em uma ordem natural e lógica. | D7: Não foram encontrados problemas. | E7: Manter a configuração do sistema
A8: 3 | B8: Controle e liberdade do usuário | C8: Os usuários geralmente escolhem as funções do sistema por engano e precisam de uma "saída de emergência" claramente marcada para deixar o estado indesejado sem ter que passar por um diálogo prolongado. Suporte para desfazer e refazer. | D8: Não foram encontrados problemas, se o usuário clicar em criar uma nova conta, mas já possuir uma conta, ele tem a opção de voltar à tela de login. | E8: Manter a configuração do sistema
A9: 4 | B9: Consistência e padrões | C9: Os usuários não devem se perguntar se palavras, situações ou ações diferentes significam a mesma coisa. | D9: Não foram encontrados problemas. | E9: Manter a configuração do sistema
A10: 5 | B10: Prevenção de erros | C10: Elimine condições propensas a erros ou verifique-as e apresente aos usuários uma opção de confirmação antes que eles se comprometam com a ação. | D10: Não foram encontrados problemas. | E10: Manter a configuração do sistema
A11: 6 | B11: Reconhecimento em vez de recordação | C11: Minimize a carga de memória do usuário, tornando objetos, ações e opções visíveis. O usuário não deve ter que lembrar informações de uma parte do diálogo para outra. As instruções de uso do sistema devem ser visíveis ou facilmente recuperáveis sempre que apropriado. | D11: Não foram encontrados problemas, a tela de login é limpa e sugestiva às ações do usuário. | E11: Manter a configuração do sistema
A12: 7 | B12: Flexibilidade e eficiência de uso | C12: Aceleradores - invisíveis para o usuário iniciante - geralmente aceleram a interação do usuário experiente, de modo que o sistema possa atender a usuários inexperientes e experientes. Permita que os usuários adaptem ações frequentes. | D12: Não foram encontrados problemas. | E12: Manter a configuração do sistema
A13: 8 | B13: Design estético e minimalista | C13: Os diálogos não devem conter informações irrelevantes ou raramente necessárias. Cada unidade extra de informação em um diálogo concorre com as unidades relevantes de informação e diminui sua visibilidade relativa. | D13: Não foram encontrados problemas. | E13: Manter a configuração do sistema
A14: 9 | B14: Ajude os usuários a reconhecer, diagnosticar e recuperar de erros | C14: As mensagens de erro devem ser expressas em linguagem simples (sem códigos), indicar com precisão o problema e sugerir construtivamente uma solução. | D14: Não foram encontrados problemas, as mensagens de erro de senha ou e-mail são claras e objetivas | E14: Manter a configuração do sistema
A15: 10 | B15: Ajuda e documentação | C15: Mesmo que seja melhor se o sistema puder ser usado sem documentação, pode ser necessário fornecer ajuda e documentação. Essas informações devem ser fáceis de pesquisar, focadas na tarefa do usuário, listar etapas concretas a serem executadas e não serem muito grandes. | D15: A tela de login é intuitiva e autoexplicativa, seguindo padrões de outros sistemas já existentes, portanto dispensando documentação para acessar. | E15: Manter a configuração do sistema
A17: Referência | B17: “10 Heurísticas de usabilidade para o design de interface do usuário” - por Jakob Nielsen em 24 de abril de 1994
B18: https://www.nngroup.com/articles/ten-usability-heuristics/

Sheet Consolidação
A1: Nº | B1: Problema 1 | D1: Nº | E1: Sugestao 1 | G1: Nº | H1: Problema 2 | J1: Nº | K1: Sugestao 2 | M1: Nº | N1: Problema 3 | P1: Nº | Q1: Sugestao 3
A2: 1 | B2: =IF('Parecer 1 - Caroline'!D6="","não se aplica",'Parecer 1 - Caroline'!D6) -> O sistema apresenta o dia selecionado, tarefas e agenda de forma clara. Porém, ao marcar uma tarefa como concluída, não existe uma confirmação visual muito evidente além do texto riscado. | D2: 1 | E2: =IF('Parecer 1 - Caroline'!D6="","não se aplica",'Parecer 1 - Caroline'!D6) -> O sistema apresenta o dia selecionado, tarefas e agenda de forma clara. Porém, ao marcar uma tarefa como concluída, não existe uma confirmação visual muito evidente além do texto riscado. | G2: 1 | H2: =IF('Parecer 2 - Divino'!D6="","não se aplica",'Parecer 2 - Divino'!D6) -> Não há feedback visual claro após adicionar, editar ou excluir uma tarefa. O usuário pode ficar em dúvida se a ação foi executada com sucesso. | J2: 1 | K2: =IF('Parecer 2 - Divino'!E6="","não se aplica",'Parecer 2 - Divino'!E6) -> Exibir mensagens de confirmação (toast/snackbar), como "Tarefa adicionada com sucesso" ou "Tarefa removida". | M2: 1 | N2: =IF('Parecer 3 - Felipe'!D6="","não se aplica",'Parecer 3 - Felipe'!D6) -> Não foram encontrados problemas. A página comunica claramente seu propósito e conteúdo em todas as seções. | P2: 1 | Q2: =IF('Parecer 3 - Felipe'!E6="","não se aplica",'Parecer 3 - Felipe'!E6) -> Manter a configuração atual.
A3: 2 | B3: =IF('Parecer 1 - Caroline'!D7="","não se aplica",'Parecer 1 - Caroline'!D7) -> A maior parte dos termos utilizados é familiar ao usuário, como "Hoje", "Amanhã", "Agenda do Dia" e "Tarefas". Entretanto, usuários podem não compreender imediatamente a diferença entre a visualização semanal e a agenda diária. | D3: 2 | E3: =IF('Parecer 1 - Caroline'!E7="","não se aplica",'Parecer 1 - Caroline'!E7) -> Adicionar uma breve descrição ou tooltip explicando a função de cada seção na primeira utilização. | G3: 2 | H3: =IF('Parecer 2 - Divino'!D7="","não se aplica",'Parecer 2 - Divino'!D7) -> O sistema utiliza os termos "Nova Tarefa" e "Nova Missão" para a mesma funcionalidade, podendo gerar confusão. | J3: 2 | K3: =IF('Parecer 2 - Divino'!E7="","não se aplica",'Parecer 2 - Divino'!E7) -> Padronizar a nomenclatura utilizando apenas "Tarefa" ou apenas "Missão" em todo o sistema. | M3: 2 | N3: =IF('Parecer 3 - Felipe'!D7="","não se aplica",'Parecer 3 - Felipe'!D7) -> Não foram encontrados problemas. Os textos utilizam linguagem acessível e direta ("Organize sua rotina. No seu ritmo.", "Tarefas do Dia", "Modo Foco"), compatíveis com o vocabulário do público-alvo. | P3: 2 | Q3: =IF('Parecer 3 - Felipe'!E7="","não se aplica",'Parecer 3 - Felipe'!E7) -> Manter a configuração atual.
A4: 3 | B4: =IF('Parecer 1 - Caroline'!D8="","não se aplica",'Parecer 1 - Caroline'!D8) -> O usuário consegue navegar entre semanas e selecionar qualquer dia da semana exibida. Entretanto, não existe uma forma rápida de retornar para uma data específica distante. | D4: 3 | E4: =IF('Parecer 1 - Caroline'!E8="","não se aplica",'Parecer 1 - Caroline'!E8) -> Implementar um seletor de data (Date Picker) para permitir navegação direta para qualquer dia. | G4: 3 | H4: =IF('Parecer 2 - Divino'!D8="","não se aplica",'Parecer 2 - Divino'!D8) -> Não foram identificados problemas relevantes nesta heurística. | J4: 3 | K4: =IF('Parecer 2 - Divino'!E8="","não se aplica",'Parecer 2 - Divino'!E8) -> Como melhoria futura, poderia ser adicionada uma opção de "Desfazer" após a exclusão para aumentar ainda mais o controle do usuário. | M4: 3 | N4: =IF('Parecer 3 - Felipe'!D8="","não se aplica",'Parecer 3 - Felipe'!D8) -> Não foram encontrados problemas. A navegação fixa com links âncora permite ao usuário ir e voltar entre seções livremente. O scroll suave contribui para a orientação espacial na página. | P4: 3 | Q4: =IF('Parecer 3 - Felipe'!E8="","não se aplica",'Parecer 3 - Felipe'!E8) -> Manter a configuração atual.
A5: 4 | B5: =IF('Parecer 1 - Caroline'!D9="","não se aplica",'Parecer 1 - Caroline'!D9) -> Os componentes seguem o mesmo padrão visual, utilizando a mesma paleta de cores, tipografia e estilo dos botões. Não foram encontrados problemas significativos. | D5: 4 | E5: =IF('Parecer 1 - Caroline'!E9="","não se aplica",'Parecer 1 - Caroline'!E9) -> Manter a padronização visual em futuras funcionalidades do sistema. | G5: 4 | H5: =IF('Parecer 2 - Divino'!D9="","não se aplica",'Parecer 2 - Divino'!D9) -> Há inconsistência terminológica entre "Tarefa" e "Missão". | J5: 4 | K5: =IF('Parecer 2 - Divino'!E9="","não se aplica",'Parecer 2 - Divino'!E9) -> Padronizar termos, ícones e nomenclaturas em todas as telas. | M5: 4 | N5: =IF('Parecer 3 - Felipe'!D9="","não se aplica",'Parecer 3 - Felipe'!D9) -> O link "Ver o App" aparece duplicado na navegação, uma vez nos nav-links (visível no menu) e outra vez como botão CTA separado. Em telas menores o CTA é ocultado via CSS, mas em desktop ambos ficam visíveis simultaneamente, o que pode causar estranhamento visual por repetição. | P5: 4 | Q5: =IF('Parecer 3 - Felipe'!E9="","não se aplica",'Parecer 3 - Felipe'!E9) -> Manter apenas o botão CTA destacado na navbar, removendo a entrada duplicada dentro dos nav-links, ou diferenciá-los visualmente com propósitos distintos.
A6: 5 | B6: =IF('Parecer 1 - Caroline'!D10="","não se aplica",'Parecer 1 - Caroline'!D10) -> Atualmente o sistema possui poucas ações críticas. Entretanto, futuras funcionalidades envolvendo exclusão de tarefas podem gerar erros de uso. | D6: 5 | E6: =IF('Parecer 1 - Caroline'!E10="","não se aplica",'Parecer 1 - Caroline'!E10) -> Adicionar confirmações para ações destrutivas, como exclusão de tarefas ou eventos. | G6: 5 | H6: =IF('Parecer 2 - Divino'!D10="","não se aplica",'Parecer 2 - Divino'!D10) -> O sistema ajuda a prevenir exclusões acidentais por meio de uma confirmação antes da remoção da tarefa. No entanto, não foram observadas validações visíveis para campos obrigatórios no cadastro de tarefas. | J6: 5 | K6: =IF('Parecer 2 - Divino'!E10="","não se aplica",'Parecer 2 - Divino'!E10) -> Manter a confirmação de exclusão e implementar validações visuais para campos obrigatórios e formatos inválidos. | M6: 5 | N6: =IF('Parecer 3 - Felipe'!D10="","não se aplica",'Parecer 3 - Felipe'!D10) -> Não foram encontrados problemas. A página é essencialmente informativa e de navegação, sem formulários ou campos de entrada que possam gerar erros de preenchimento. | P6: 5 | Q6: =IF('Parecer 3 - Felipe'!E10="","não se aplica",'Parecer 3 - Felipe'!E10) -> Manter a configuração atual.
A7: 6 | B7: =IF('Parecer 1 - Caroline'!D11="","não se aplica",'Parecer 1 - Caroline'!D11) -> As informações importantes ficam visíveis na tela, como tarefas do dia, agenda e data selecionada. O usuário não precisa memorizar informações para utilizar o sistema. | D7: 6 | E7: =IF('Parecer 1 - Caroline'!E11="","não se aplica",'Parecer 1 - Caroline'!E11) -> Continuar priorizando informações visíveis e reduzir a necessidade de navegação excessiva. | G7: 6 | H7: =IF('Parecer 2 - Divino'!D11="","não se aplica",'Parecer 2 - Divino'!D11) -> Não foram identificados problemas relevantes. | J7: 6 | K7: =IF('Parecer 2 - Divino'!E11="","não se aplica",'Parecer 2 - Divino'!E11) -> Manter o padrão atual de identificação visual e textual dos elementos da interface. | M7: 6 | N7: =IF('Parecer 3 - Felipe'!D11="","não se aplica",'Parecer 3 - Felipe'!D11) -> Não foram encontrados problemas. A navegação fixa com rótulos claros (Sobre, Funcionalidades, Screenshots, Equipe) permite que o usuário identifique visualmente onde está e para onde pode ir, sem necessidade de memorização. | P7: 6 | Q7: =IF('Parecer 3 - Felipe'!E11="","não se aplica",'Parecer 3 - Felipe'!E11) -> Manter a configuração atual.
A8: 7 | B8: =IF('Parecer 1 - Caroline'!D12="","não se aplica",'Parecer 1 - Caroline'!D12) -> Usuários iniciantes conseguem utilizar o calendário facilmente. Porém, usuários mais experientes podem sentir falta de atalhos ou navegação mais rápida. | D8: 7 | E8: =IF('Parecer 1 - Caroline'!E12="","não se aplica",'Parecer 1 - Caroline'!E12) -> Adicionar atalhos de teclado e filtros rápidos para melhorar a produtividade. | G8: 7 | H8: =IF('Parecer 2 - Divino'!D12="","não se aplica",'Parecer 2 - Divino'!D12) -> Não foram identificados problemas relevantes | J8: 7 | K8: =IF('Parecer 2 - Divino'!E12="","não se aplica",'Parecer 2 - Divino'!E12) -> Manter a organização atual das ações rápidas, garantindo que continuem facilmente acessíveis aos usuários. | M8: 7 | N8: =IF('Parecer 3 - Felipe'!D12="","não se aplica",'Parecer 3 - Felipe'!D12) -> O cursor personalizado é ativado apenas para telas acima de 600px. Em dispositivos móveis a experiência é padrão, o que é adequado. Porém, não há indicador de seção ativa no menu de navegação, o que reduziria a eficiência de orientação para usuários experientes. | P8: 7 | Q8: =IF('Parecer 3 - Felipe'!E12="","não se aplica",'Parecer 3 - Felipe'!E12) -> Implementar destaque visual no link de navegação correspondente à seção visível no momento, melhorando a orientação para todos os perfis de usuário.
A9: 8 | B9: =IF('Parecer 1 - Caroline'!D13="","não se aplica",'Parecer 1 - Caroline'!D13) -> A interface possui visual limpo, organizado e agradável, utilizando uma paleta suave e poucas distrações visuais. Não foram identificados problemas relevantes. | D9: 8 | E9: =IF('Parecer 1 - Caroline'!E13="","não se aplica",'Parecer 1 - Caroline'!E13) -> Manter o design minimalista e evitar excesso de informações na tela principal. | G9: 8 | H9: =IF('Parecer 2 - Divino'!D13="","não se aplica",'Parecer 2 - Divino'!D13) -> O design é limpo e organizado, porém alguns textos possuem contraste baixo com o fundo, dificultando a leitura. | J9: 8 | K9: =IF('Parecer 2 - Divino'!E13="","não se aplica",'Parecer 2 - Divino'!E13) -> Melhorar o contraste dos rótulos secundários e informações menores para aumentar a acessibilidade. | M9: 8 | N9: =IF('Parecer 3 - Felipe'!D13="","não se aplica",'Parecer 3 - Felipe'!D13) -> Não foram encontrados problemas. O layout é limpo, com hierarquia visual clara, paleta coesa e sem elementos decorativos excessivos. As seções são bem delimitadas e o conteúdo é direto ao ponto. | P9: 8 | Q9: =IF('Parecer 3 - Felipe'!E13="","não se aplica",'Parecer 3 - Felipe'!E13) -> Manter a configuração atual.
A10: 9 | B10: =IF('Parecer 1 - Caroline'!D14="","não se aplica",'Parecer 1 - Caroline'!D14) -> Não existem mensagens de erro porque a aplicação ainda não possui integração com backend. Em futuras versões, falhas de carregamento ou salvamento podem não ficar claras ao usuário. | D10: 9 | E10: =IF('Parecer 1 - Caroline'!E14="","não se aplica",'Parecer 1 - Caroline'!E14) -> Implementar mensagens amigáveis de erro e feedback para operações futuras envolvendo banco de dados ou APIs. | G10: 9 | H10: =IF('Parecer 2 - Divino'!D14="","não se aplica",'Parecer 2 - Divino'!D14) -> Não são apresentadas mensagens de erro ou orientações quando ocorre um problema de preenchimento ou operação inválida. | J10: 9 | K10: =IF('Parecer 2 - Divino'!E14="","não se aplica",'Parecer 2 - Divino'!E14) -> Exibir mensagens claras explicando o erro e orientando o usuário sobre como corrigi-lo. | M10: 9 | N10: =IF('Parecer 3 - Felipe'!D14="","não se aplica",'Parecer 3 - Felipe'!D14) -> Não se aplica diretamente, pois a landing page não possui interações que gerem estados de erro (sem formulários, sem login, sem buscas). A página é essencialmente informativa e não expõe o usuário a situações de erro. | P10: 9 | Q10: =IF('Parecer 3 - Felipe'!E14="","não se aplica",'Parecer 3 - Felipe'!E14) -> Manter a configuração atual.
A11: 10 | B11: =IF('Parecer 1 - Caroline'!D15="","não se aplica",'Parecer 1 - Caroline'!D15) -> Não há uma seção de ajuda ou explicação das funcionalidades para novos usuários. Usuários podem precisar explorar a interface para compreender todas as funcionalidades. | D11: 10 | E11: =IF('Parecer 1 - Caroline'!E15="","não se aplica",'Parecer 1 - Caroline'!E15) -> Adicionar uma tela de onboarding, tutorial inicial ou seção de ajuda explicando os recursos do calendário. | G11: 10 | H11: =IF('Parecer 2 - Divino'!D15="","não se aplica",'Parecer 2 - Divino'!D15) -> Não há opção visível de ajuda, tutorial inicial ou seção de dúvidas frequentes. | J11: 10 | K11: =IF('Parecer 2 - Divino'!E15="","não se aplica",'Parecer 2 - Divino'!E15) -> Adicionar um guia rápido de utilização, FAQ ou tour inicial para novos usuários. | M11: 10 | N11: =IF('Parecer 3 - Felipe'!D15="","não se aplica",'Parecer 3 - Felipe'!D15) -> Não foram encontrados problemas. A landing page é autoexplicativa, com descrições claras de cada funcionalidade do app nas feature cards. O público-alvo consegue compreender o propósito do sistema sem necessidade de documentação adicional. | P11: 10 | Q11: =IF('Parecer 3 - Felipe'!E15="","não se aplica",'Parecer 3 - Felipe'!E15) -> Manter a configuração atual.
A13: Nº | B13: Problema 4 | D13: Nº | E13: Sugestao 4 | G13: Nº | H13: Problema 5 | J13: Nº | K13: Sugestao 5 | M13: Nº | N13: Problema 6 | P13: Nº | Q13: Sugestao 6
